Workbook

Sheet Dashboard
B1: BAIG Press — FINANCIAL DASHBOARD
B3: Company Name: | C3: Baig Press Haripur
B4: Report Period: | C4: October 2026
B5: Prepared On: | C5: 2026-10-18
B7: KEY PERFORMANCE INDICATORS
B8: Metric | C8: Amount / Value | D8: Notes
B9: Total Revenue | C9: ='Monthly P&L'!C20 -> 59000 | D9: All income streams combined
B10: Total Expenses | C10: ='Monthly P&L'!C36 -> 30016.5 | D10: Operating + COGS + Overhead
B11: Gross Profit | C11: ='Monthly P&L'!C22 -> 51548 | D11: Revenue minus Cost of Goods Sold
B12: Net Profit | C12: ='Monthly P&L'!C38 -> 21531.5 | D12: After all expenses & salaries
B13: Profit Margin % | C13: ='Monthly P&L'!C39 -> 21531.5 | D13: Net Profit / Total Revenue
B14: Total Salaries | C14: =Payroll!#REF! -> #REF! | D14: Monthly payroll total
B15: Cash / Savings | C15: ='Cash Flow'!G18 -> 0 | D15: Bank + Petty Cash + Reserves
B16: Outstanding Payables | C16: =Expenses!G50 -> 15974 | D16: Unpaid supplier invoices
B18: MONTHLY SNAPSHOT (Current Year)
B19: Month | C19: Revenue | D19: Expenses | E19: Salaries | F19: Net Profit | G19: Savings Add
B20: Jan | C20: 48500 | D20: 31200 | E20: 18500 | F20: =C20-D20-E20 -> -1200 | G20: 3000
B21: Feb | C21: 51200 | D21: 29800 | E21: 18500 | F21: =C21-D21-E21 -> 2900 | G21: 3500
B22: Mar | C22: 47800 | D22: 32500 | E22: 18500 | F22: =C22-D22-E22 -> -3200 | G22: 2500
B23: Apr | C23: 53400 | D23: 30100 | E23: 19000 | F23: =C23-D23-E23 -> 4300 | G23: 4000
B24: May | C24: 56100 | D24: 31800 | E24: 19000 | F24: =C24-D24-E24 -> 5300 | G24: 4500
B25: Jun | C25: 52900 | D25: 33200 | E25: 19000 | F25: =C25-D25-E25 -> 700 | G25: 3200
B26: Jul | C26: 49500 | D26: 30900 | E26: 19500 | F26: =C26-D26-E26 -> -900 | G26: 2800
B27: Aug | C27: 54800 | D27: 32100 | E27: 19500 | F27: =C27-D27-E27 -> 3200 | G27: 3800
B28: Sep | C28: 58200 | D28: 33500 | E28: 19500 | F28: =C28-D28-E28 -> 5200 | G28: 4200
B29: Oct | C29: 61500 | D29: 34800 | E29: 20000 | F29: =C29-D29-E29 -> 6700 | G29: 5000
B30: Nov
B31: Dec
B32: YTD TOTAL | C32: =SUM(C20:C31) -> 533900 | D32: =SUM(D20:D31) -> 319900 | E32: =SUM(E20:E31) -> 191000 | F32: =SUM(F20:F31) -> 23000 | G32: =SUM(G20:G31) -> 36500
B34: HOW TO USE THIS WORKBOOK
B35: 1. Yellow cells with BLUE text are INPUT cells — edit these with your actual figures.
B36: 2. Black text cells contain FORMULAS — do not overwrite them.
B37: 3. Start with the 'Revenue' sheet to log sales/jobs, then 'Expenses', then 'Payroll'.
B38: 4. 'Monthly P&L' automatically calculates profit from the other sheets.
B39: 5. 'Cash Flow' tracks bank balances, savings, and reserves.
B40: 6. Update the Dashboard monthly snapshot with your real monthly totals.
B41: 7. All currency is in USD. Change the company name and period in the yellow cells above.

Sheet Revenue
B1: REVENUE & JOB LOG — BAIGPress
B3: Date | C3: Invoice # | D3: Client / Job Name | E3: Service Type | F3: Quantity | G3: Unit Price | H3: Gross Amount | I3: Discount | J3: Net Amount | K3: Payment Status | L3: Notes
B4: 46296 | C4: INV-1001 | D4: Metro Bank Brochure Run | E4: Offset Printing | F4: 5000 | G4: 0.85 | H4: =F4*G4 -> 4250 | I4: 0 | J4: =H4-I4 -> 4250 | K4: Paid | L4: Glossy cover
B5: 46297 | C5: INV-1002 | D5: City Council Flyers | E5: Digital Print | F5: 10000 | G5: 0.12 | H5: =F5*G5 -> 1200 | I5: 50 | J5: =H5-I5 -> 1150 | K5: Paid | L5: A5 flyers
B6: 46298 | C6: INV-1003 | D6: Sunrise Hotel Menus | E6: Offset + Lamination | F6: 2000 | G6: 1.45 | H6: =F6*G6 -> 2900 | I6: 0 | J6: =H6-I6 -> 2900 | K6: Pending | L6: Menu cards
B7: 46299 | C7: INV-1004 | D7: TechStart Business Cards | E7: Digital Print | F7: 1000 | G7: 0.25 | H7: =F7*G7 -> 250 | I7: 0 | J7: =H7-I7 -> 250 | K7: Paid | L7: Premium stock
B8: 46300 | C8: INV-1005 | D8: GreenLeaf Catalog | E8: Offset Printing | F8: 3000 | G8: 2.1 | H8: =F8*G8 -> 6300 | I8: 150 | J8: =H8-I8 -> 6150 | K8: Paid | L8: 32-page catalog
B9: 46302 | C9: INV-1006 | D9: AutoZone Posters | E9: Large Format | F9: 50 | G9: 18 | H9: =F9*G9 -> 900 | I9: 0 | J9: =H9-I9 -> 900 | K9: Pending | L9: A1 posters
B10: 46303 | C10: INV-1007 | D10: School Yearbook | E10: Offset + Binding | F10: 800 | G10: 12.5 | H10: =F10*G10 -> 10000 | I10: 200 | J10: =H10-I10 -> 9800 | K10: Paid | L10: Hard cover
B11: 46304 | C11: INV-1008 | D11: Cafe Loyalty Cards | E11: Digital Print | F11: 5000 | G11: 0.08 | H11: =F11*G11 -> 400 | I11: 0 | J11: =H11-I11 -> 400 | K11: Paid | L11: PVC cards
B12: 46305 | C12: INV-1009 | D12: Real Estate Brochures | E12: Offset Printing | F12: 2500 | G12: 1.2 | H12: =F12*G12 -> 3000 | I12: 100 | J12: =H12-I12 -> 2900 | K12: Pending | L12: Tri-fold
B13: 46306 | C13: INV-1010 | D13: Wedding Invitations | E13: Digital + Foil | F13: 300 | G13: 3.5 | H13: =F13*G13 -> 1050 | I13: 0 | J13: =H13-I13 -> 1050 | K13: Paid | L13: Foil stamping
B14: 46307 | C14: INV-1011 | D14: Pharma Product Labels | E14: Digital Print | F14: 15000 | G14: 0.05 | H14: =F14*G14 -> 750 | I14: 0 | J14: =H14-I14 -> 750 | K14: Paid | L14: Roll labels
B15: 46309 | C15: INV-1012 | D15: University Handbooks | E15: Offset + Binding | F15: 1500 | G15: 4.75 | H15: =F15*G15 -> 7125 | I15: 300 | J15: =H15-I15 -> 6825 | K15: Pending | L15: Soft cover
... B18: 46312 | C18: INV-1015 | D18: Restaurant Takeout Menus | E18: Digital Print | F18: 3000 | G18: 0.35 | H18: =F18*G18 -> 1050 | I18: 50 | J18: =H18-I18 -> 1000 | K18: Pending | L18: Waterproof
B19: 46313 | H19: =IF(F19="","",F19*G19) | J19: =IF(H19="","",H19-I19)
H20: =IF(F20="","",F20*G20) | J20: =IF(H20="","",H20-I20)
H21: =IF(F21="","",F21*G21) | J21: =IF(H21="","",H21-I21)
H22: =IF(F22="","",F22*G22) | J22: =IF(H22="","",H22-I22)
H23: =IF(F23="","",F23*G23) | J23: =IF(H23="","",H23-I23)
H24: =IF(F24="","",F24*G24) | J24: =IF(H24="","",H24-I24)
H25: =IF(F25="","",F25*G25) | J25: =IF(H25="","",H25-I25)
H26: =IF(F26="","",F26*G26) | J26: =IF(H26="","",H26-I26)
H27: =IF(F27="","",F27*G27) | J27: =IF(H27="","",H27-I27)
H28: =IF(F28="","",F28*G28) | J28: =IF(H28="","",H28-I28)
H29: =IF(F29="","",F29*G29) | J29: =IF(H29="","",H29-I29)
H30: =IF(F30="","",F30*G30) | J30: =IF(H30="","",H30-I30)
H31: =IF(F31="","",F31*G31) | J31: =IF(H31="","",H31-I31)
... H43: =IF(F43="","",F43*G43) | J43: =IF(H43="","",H43-I43)
B45: TOTALS | F45: =SUM(F4:F43) -> 59170 | H45: =SUM(H4:H43) -> 40975 | I45: =SUM(I4:I43) -> 850 | J45: =SUM(J4:J43) -> 40125
B47: PAYMENT STATUS SUMMARY
B48: Status | C48: Count | D48: Total Amount
B49: Paid | C49: =COUNTIF(K4:K43,"Paid") -> 10 | D49: =SUMIF(K4:K43,"Paid",J4:J43) -> 25600
B50: Pending | C50: =COUNTIF(K4:K43,"Pending") -> 5 | D50: =SUMIF(K4:K43,"Pending",J4:J43) -> 14525
B51: Overdue | C51: =COUNTIF(K4:K43,"Overdue") -> 0 | D51: =SUMIF(K4:K43,"Overdue",J4:J43) -> 0

Sheet Expenses
B1: EXPENSE TRACKER — BAIGPress
B3: Date | C3: Ref / Invoice | D3: Vendor / Supplier | E3: Category | F3: Description | G3: Amount | H3: Tax / VAT | I3: Total | J3: Payment Status | K3: Notes
B4: 46296 | C4: PO-501 | D4: PaperWorld Supplies | E4: Paper & Substrates | F4: A4 Glossy 150gsm - 50 reams | G4: 1850 | H4: 185 | I4: =G4+H4 -> 2035 | J4: Paid | K4: Monthly stock
B5: 46296 | C5: PO-502 | D5: InkPro Ltd | E5: Ink & Toners | F5: CMYK process inks set | G5: 920 | H5: 92 | I5: =G5+H5 -> 1012 | J5: Paid | K5: Offset inks
B6: 46297 | C6: UTIL-1001 | D6: City Power Co | E6: Utilities - Electricity | F6: September electricity bill | G6: 2450 | H6: 0 | I6: =G6+H6 -> 2450 | J6: Paid | K6: High usage month
B7: 46298 | C7: RENT-10 | D7: Prime Properties | E7: Rent / Facility | F7: October warehouse rent | G7: 4500 | H7: 0 | I7: =G7+H7 -> 4500 | J7: Paid | K7: Main facility
B8: 46299 | C8: PO-503 | D8: ChemPrint Inc | E8: Chemicals & Plates | F8: Fountain solution + plates | G8: 680 | H8: 68 | I8: =G8+H8 -> 748 | J8: Pending | K8: CTP plates
B9: 46300 | C9: MAINT-88 | D9: PressCare Services | E9: Equipment Maintenance | F9: Heidelberg press service | G9: 1200 | H9: 120 | I9: =G9+H9 -> 1320 | J9: Paid | K9: Quarterly service
B10: 46301 | C10: INS-2026 | D10: SafeGuard Insurance | E10: Insurance | F10: Annual equipment insurance (1/12) | G10: 450 | H10: 0 | I10: =G10+H10 -> 450 | J10: Paid | K10: Monthly portion
B11: 46302 | C11: DEL-301 | D11: FastFreight Logistics | E11: Transportation & Delivery | F11: Client deliveries - Week 1 | G11: 380 | H11: 38 | I11: =G11+H11 -> 418 | J11: Paid | K11: Local + regional
B12: 46303 | C12: MKT-45 | D12: Local Ads Media | E12: Marketing & Advertising | F12: Google Ads + flyer campaign | G12: 550 | H12: 55 | I12: =G12+H12 -> 605 | J12: Pending | K12: Lead gen
B13: 46304 | C13: PO-504 | D13: PaperWorld Supplies | E13: Paper & Substrates | F13: Cardstock 300gsm - 20 packs | G13: 720 | H13: 72 | I13: =G13+H13 -> 792 | J13: Paid | K13: Business cards
B14: 46305 | C14: SOFT-12 | D14: Adobe / PrintSoft | E14: Software & Licenses | F14: Adobe CC + RIP software | G14: 89 | H14: 0 | I14: =G14+H14 -> 89 | J14: Paid | K14: Monthly sub
B15: 46306 | C15: UTIL-1002 | D15: Water & Gas Co | E15: Utilities - Other | F15: Water + gas bill | G15: 210 | H15: 0 | I15: =G15+H15 -> 210 | J15: Paid
B16: 46307 | C16: PO-505 | D16: InkPro Ltd | E16: Ink & Toners | F16: Digital toner cartridges | G16: 640 | H16: 64 | I16: =G16+H16 -> 704 | J16: Pending | K16: HP Indigo
B17: 46309 | C17: OFF-22 | D17: OfficeMart | E17: Office Supplies | F17: Stationery & packing materials | G17: 175 | H17: 17.5 | I17: =G17+H17 -> 192.5 | J17: Paid
B18: 46310 | C18: ACCT-09 | D18: Johnson & Co CPAs | E18: Professional Fees | F18: Bookkeeping - September | G18: 350 | H18: 0 | I18: =G18+H18 -> 350 | J18: Pending | K18: Monthly retainer
B19: 46311 | C19: DEL-302 | D19: FastFreight Logistics | E19: Transportation & Delivery | F19: Client deliveries - Week 2 | G19: 420 | H19: 42 | I19: =G19+H19 -> 462 | J19: Paid
B20: 46312 | C20: PO-506 | D20: PaperWorld Supplies | E20: Paper & Substrates | F20: Specialty textured paper | G20: 390 | H20: 39 | I20: =G20+H20 -> 429 | J20: Paid | K20: Wedding inv.
I21: =IF(G21="","",G21+H21)
I22: =IF(G22="","",G22+H22)
I23: =IF(G23="","",G23+H23)
I24: =IF(G24="","",G24+H24)
I25: =IF(G25="","",G25+H25)
I26: =IF(G26="","",G26+H26)
I27: =IF(G27="","",G27+H27)
I28: =IF(G28="","",G28+H28)
I29: =IF(G29="","",G29+H29)
I30: =IF(G30="","",G30+H30)
I31: =IF(G31="","",G31+H31)
I32: =IF(G32="","",G32+H32)
... I48: =IF(G48="","",G48+H48)
B50: TOTALS | G50: =SUM(G4:G48) -> 15974 | H50: =SUM(H4:H48) -> 792.5 | I50: =SUM(I4:I48) -> 16766.5
B52: EXPENSE BY CATEGORY
B53: Category | C53: Total Amount | D53: % of Total
B54: Paper & Substrates | C54: =SUMIF(E$4:E$48,B54,I$4:I$48) -> 3256 | D54: =IF($I$50=0,0,C54/$I$50) -> 0.19419676
B55: Ink & Toners | C55: =SUMIF(E$4:E$48,B55,I$4:I$48) -> 1716 | D55: =IF($I$50=0,0,C55/$I$50) -> 0.10234694
B56: Chemicals & Plates | C56: =SUMIF(E$4:E$48,B56,I$4:I$48) -> 748 | D56: =IF($I$50=0,0,C56/$I$50) -> 0.04461277
B57: Equipment Maintenance | C57: =SUMIF(E$4:E$48,B57,I$4:I$48) -> 1320 | D57: =IF($I$50=0,0,C57/$I$50) -> 0.078728417
B58: Utilities - Electricity | C58: =SUMIF(E$4:E$48,B58,I$4:I$48) -> 2450 | D58: =IF($I$50=0,0,C58/$I$50) -> 0.14612471
...

Sheet Payroll
B1: PAYROLL & SALARIES — BAIGPress
B2: Pay Period: | C2: October 1–31, 2026 | E2: Pay Date: | F2: 46326
B4: # | C4: Employee Name | D4: Position / Role | E4: Employment Type | F4: Basic Salary | G4: Overtime | H4: Allowances | I4: Gross Pay | J4: Tax / Deductions | K4: Other Deduct. | L4: Net Pay | M4: Payment Method | N4: Status
B5: 1 | C5: Iftikhar Baig | D5: Press Operator (Lead) | E5: Full-time | F5: 5000 | G5: 200 | H5: 200 | I5: =F5+G5+H5 -> 5400 | J5: 420 | K5: 50 | L5: =I5-J5-K5 -> 4930 | M5: Bank Transfer | N5: Paid
B6: 2 | C6: Eisha Pervez | D6: Accountant | E6: Full-time | F6: 1900 | G6: 180 | H6: 80 | I6: =F6+G6+H6 -> 2160 | J6: 285 | K6: 15 | L6: =I6-J6-K6 -> 1860 | M6: Bank Transfer | N6: Paid
B7: 3 | C7: Zulkifl Rabani | D7: Graphic Designer | E7: Full-time | F7: 4000 | G7: 120 | H7: 150 | I7: =F7+G7+H7 -> 4270 | J7: 360 | K7: 30 | L7: =I7-J7-K7 -> 3880 | M7: Bank Transfer | N7: Pending
B8: 4 | C8: Abdul Mohiz Baig | D8: Laser Print Tech | E8: Full-time | F8: 4500 | G8: 200 | H8: 100 | I8: =F8+G8+H8 -> 4800 | J8: 330 | K8: 20 | L8: =I8-J8-K8 -> 4450 | M8: Bank Transfer | N8: Paid
B9: 5 | C9: Uziafa Baig | D9: Prepress / CTP | E9: Part-time | F9: 2100 | G9: 100 | H9: 100 | I9: =F9+G9+H9 -> 2300 | J9: 315 | K9: 25 | L9: =I9-J9-K9 -> 1960 | M9: Bank Transfer | N9: Paid
B10: 6 | C10: Ahmed Shah | D10: Sales & Customer Svc | E10: Part-time | F10: 2000 | G10: 0 | H10: 250 | I10: =F10+G10+H10 -> 2250 | J10: 300 | K10: 40 | L10: =I10-J10-K10 -> 1910 | M10: Bank Transfer | N10: Paid
C12: TOTALS | F12: =SUM(F5:F10) -> 19500 | G12: =SUM(G5:G10) -> 800 | H12: =SUM(H5:H10) -> 880 | I12: =SUM(I5:I10) -> 21180 | J12: =SUM(J5:J10) -> 2010 | K12: =SUM(K5:K10) -> 180 | L12: =SUM(L5:L10) -> 18990
B14: PAYROLL SUMMARY
B15: Total Gross Payroll: | C15: =I12 -> 21180 | E15: Full-time Staff: | F15: =COUNTIF(E5:E10,"Full-time") -> 4
B16: Total Deductions: | C16: =J12+K12 -> 2190 | E16: Part-time Staff: | F16: =COUNTIF(E5:E10,"Part-time") -> 2
B17: Total Net Pay: | C17: =L12 -> 18990
B18: Headcount: | C18: =COUNTA(C5:C10) -> 6

Sheet Monthly P&L
B1: PROFIT & LOSS STATEMENT — BAIGPress
B2: Period: | C2: October 2026
B3: Currency: | C3: USD ($)
B5: Description | C5: Amount | D5: % of Revenue
B6: REVENUE
B7: Offset Printing Services | C7: 28500 | D7: =IF($C$20=0,0,C7/$C$20) -> 0.48305085
B8: Digital Printing Services | C8: 14200 | D8: =IF($C$20=0,0,C8/$C$20) -> 0.24067797
B9: Large Format Printing | C9: 4200 | D9: =IF($C$20=0,0,C9/$C$20) -> 0.071186441
B10: Binding & Finishing | C10: 6800 | D10: =IF($C$20=0,0,C10/$C$20) -> 0.11525424
B11: Design & Prepress Services | C11: 3500 | D11: =IF($C$20=0,0,C11/$C$20) -> 0.059322034
B12: Other Income | C12: 1800 | D12: =IF($C$20=0,0,C12/$C$20) -> 0.030508475
B14: COST OF GOODS SOLD (COGS)
B15: Paper & Substrates | C15: 2960 | D15: =IF($C$20=0,0,C15/$C$20) -> 0.050169492
B16: Ink, Toners & Chemicals | C16: 2464 | D16: =IF($C$20=0,0,C16/$C$20) -> 0.041762712
B17: Plates & Consumables | C17: 748 | D17: =IF($C$20=0,0,C17/$C$20) -> 0.012677966
B18: Direct Labor (Production OT) | C18: 1280 | D18: =IF($C$20=0,0,C18/$C$20) -> 0.021694915
B19: Total COGS | C19: =SUM(C15:C18) -> 7452 | D19: =IF($C$20=0,0,C19/$C$20) -> 0.12630508
B20: TOTAL REVENUE | C20: =SUM(C7:C12) -> 59000 | D20: =1 -> 1
B22: GROSS PROFIT | C22: =C20-C19 -> 51548 | D22: =IF($C$20=0,0,C22/$C$20) -> 0.87369492
B24: OPERATING EXPENSES
B25: Salaries & Wages (Net of OT in COGS) | C25: 18720 | D25: =IF($C$20=0,0,C25/$C$20) -> 0.31728814
B26: Rent / Facility | C26: 4500 | D26: =IF($C$20=0,0,C26/$C$20) -> 0.076271186
B27: Utilities (Electricity + Other) | C27: 2660 | D27: =IF($C$20=0,0,C27/$C$20) -> 0.045084746
B28: Equipment Maintenance | C28: 1320 | D28: =IF($C$20=0,0,C28/$C$20) -> 0.022372881
B29: Insurance | C29: 450 | D29: =IF($C$20=0,0,C29/$C$20) -> 0.0076271186
B30: Transportation & Delivery | C30: 880 | D30: =IF($C$20=0,0,C30/$C$20) -> 0.014915254
B31: Marketing & Advertising | C31: 605 | D31: =IF($C$20=0,0,C31/$C$20) -> 0.010254237
B32: Software & Licenses | C32: 89 | D32: =IF($C$20=0,0,C32/$C$20) -> 0.0015084746
B33: Office Supplies | C33: 192.5 | D33: =IF($C$20=0,0,C33/$C$20) -> 0.0032627119
B34: Professional Fees | C34: 350 | D34: =IF($C$20=0,0,C34/$C$20) -> 0.0059322034
B35: Miscellaneous / Other | C35: 250 | D35: =IF($C$20=0,0,C35/$C$20) -> 0.0042372881
B36: Total Operating Expenses | C36: =SUM(C25:C35) -> 30016.5 | D36: =IF($C$20=0,0,C36/$C$20) -> 0.50875424
B38: NET PROFIT / (LOSS) | C38: =C22-C36 -> 21531.5 | D38: =IF($C$20=0,0,C38/$C$20) -> 0.36494068
B39: Net Profit Margin | C39: =C38 -> 21531.5 | D39: =IF($C$20=0,0,C38/$C$20) -> 0.36494068
B41: NOTES
B42: • Yellow cells are editable inputs. Update them monthly from Revenue, Expenses, and Payroll sheets.
B43: • Gross Profit = Total Revenue − Cost of Goods Sold (direct production costs).
B44: • Net Profit = Gross Profit − Operating Expenses (including salaries).
B45: • Link COGS paper/ink totals from the Expenses sheet category summary for accuracy.
B46: • Salaries figure should match the Payroll sheet Gross Pay total (adjust OT allocation as needed).

Sheet Cash Flow
B1: CASH FLOW & SAVINGS TRACKER — BAIGPress
B2: As of: | C2: 46313
B4: OPENING BALANCES
B5: Account | C5: Opening Balance | D5: Notes
B6: Operating Bank Account | C6: 28500 | D6: Main business account
B7: Petty Cash | C7: 500 | D7: Office float
B8: Savings / Reserve Account | C8: 42000 | D8: Emergency & growth fund
B9: Tax Reserve Account | C9: 8500 | D9: VAT / tax set-aside
B10: Total Opening Cash | C10: =SUM(C6:C9) -> 79500
B12: CASH MOVEMENTS — THIS MONTH
B13: Description | C13: Inflows | D13: Outflows | E13: Net
B14: Customer Receipts (Paid Invoices) | C14: 41200 | E14: =IF(AND(C14="",D14=""),"",IF(C14="",0,C14)-IF(D14="",0,D14)) -> 41200
B15: Other Income Received | C15: 1800 | E15: =IF(AND(C15="",D15=""),"",IF(C15="",0,C15)-IF(D15="",0,D15)) -> 1800
B16: Supplier Payments | D16: 12500 | E16: =IF(AND(C16="",D16=""),"",IF(C16="",0,C16)-IF(D16="",0,D16)) -> -12500
B17: Payroll / Salaries Paid | D17: 18720 | E17: =IF(AND(C17="",D17=""),"",IF(C17="",0,C17)-IF(D17="",0,D17)) -> -18720
B18: Rent & Utilities Paid | D18: 7160 | E18: =IF(AND(C18="",D18=""),"",IF(C18="",0,C18)-IF(D18="",0,D18)) -> -7160
B19: Other Operating Payments | D19: 3850 | E19: =IF(AND(C19="",D19=""),"",IF(C19="",0,C19)-IF(D19="",0,D19)) -> -3850
B20: Transfer to Savings | D20: 5000 | E20: =IF(AND(C20="",D20=""),"",IF(C20="",0,C20)-IF(D20="",0,D20)) -> -5000
B21: Owner Drawings | D21: 2000 | E21: =IF(AND(C21="",D21=""),"",IF(C21="",0,C21)-IF(D21="",0,D21)) -> -2000
B22: Net Cash Movement | C22: =SUM(C14:C21) -> 43000 | D22: =SUM(D14:D21) -> 49230 | E22: =C22-D22 -> -6230
B24: CLOSING BALANCES
B25: Account | C25: Closing Balance | D25: Change
B26: Operating Bank Account | C26: =C6+C22 -> 71500 | D26: =C26-C6 -> 43000
B27: Petty Cash | C27: =C7 -> 500 | D27: =C27-C7 -> 0
B28: Savings / Reserve Account | C28: =C8+5000 -> 47000 | D28: =C28-C8 -> 5000
B29: Tax Reserve Account | C29: =C9 -> 8500 | D29: =C29-C9 -> 0
B30: TOTAL CLOSING CASH | C30: =SUM(C26:C29) -> 127500 | D30: =C30-C10 -> 48000
B32: SAVINGS GOALS & RESERVES
B33: Goal | C33: Target | D33: Current | E33: % Achieved
B34: Emergency Fund (3 months opex) | C34: 90000 | D34: 42000 | E34: =IF(C34=0,0,D34/C34) -> 0.46666667
B35: Equipment Replacement Fund | C35: 25000 | D35: 8500 | E35: =IF(C35=0,0,D35/C35) -> 0.34
B36: Growth / Expansion Fund | C36: 50000 | D36: 0 | E36: =IF(C36=0,0,D36/C36) -> 0
B37: Tax Reserve Buffer | C37: 12000 | D37: 8500 | E37: =IF(C37=0,0,D37/C37) -> 0.70833333

Sheet Chart Data
B1: CHART DATA & QUICK REFERENCE
B3: This sheet holds summary data used for charts and quick lookups.
B5: Expense Categories (for charts)
B6: Category | C6: Amount
B7: Paper & Substrates | C7: 2960
B8: Ink & Chemicals | C8: 2464
B9: Utilities | C9: 2660
B10: Rent | C10: 4500
B11: Salaries | C11: 18720
B12: Maintenance | C12: 1320
B13: Transport | C13: 880
B14: Marketing | C14: 605
B15: Other OpEx | C15: 881.5
B18: Monthly Trend (from Dashboard)
B19: Month | C19: Revenue | D19: Expenses | E19: Net Profit
B20: Jan | C20: 48500 | D20: 49700 | E20: -1200
B21: Feb | C21: 51200 | D21: 48300 | E21: 2900
B22: Mar | C22: 47800 | D22: 51000 | E22: -3200
B23: Apr | C23: 53400 | D23: 49100 | E23: 4300
B24: May | C24: 56100 | D24: 50800 | E24: 5300
B25: Jun | C25: 52900 | D25: 52200 | E25: 700
B26: Jul | C26: 49500 | D26: 50400 | E26: -900
B27: Aug | C27: 54800 | D27: 51600 | E27: 3200
B28: Sep | C28: 58200 | D28: 53000 | E28: 5200
B29: Oct | C29: 61500 | D29: 54800 | E29: 6700

Sheet Instruction
A1: Sheets included:
A3: Sheet | B3: Purpose
A4: Dashboard | B4: Overview of KPIs (Revenue, Expenses, Gross/Net Profit, Salaries, Cash/Savings), monthly snapshot, and instructions
A5: Revenue | B5: Job/invoice log with Date, Invoice #, Client, Service Type, Qty, Unit Price, Gross/Net Amount, Payment Status
A6: Expenses | B6: Full expense tracker (Paper, Ink, Chemicals, Utilities, Rent, Maintenance, Transport, Marketing, etc.) + category summary + outstanding payables
A7: Payroll | B7: Employee salaries with Basic Pay, Overtime, Allowances, Tax/Deductions, Net Pay, Payment Method & Status
A8: Monthly P&L | B8: Profit & Loss statement (Revenue → COGS → Gross Profit → Operating Expenses → Net Profit + margins)
A9: Cash Flow | B9: Opening/closing balances, cash movements, savings goals & reserves
A10: Chart Data | B10: Pie chart (expense breakdown) + line chart (Revenue vs Expenses vs Profit trend)
A12: Key features:
A14: Blue text + yellow cells = editable inputs (enter your real figures here)
A15: Black text = formulas (auto-calculate totals, net pay, profit, etc.)
A16: Dropdown lists for Service Type, Payment Status, Expense Category, Employment Type
A17: Sample data for October 2026 so you can see how it works
A18: Ready for monthly use — just update the yellow input cells
A20: You can replace the sample data with your actual numbers. The Dashboard and P&L will update automatically once the formulas recalculate in Excel.
